<?xml version="1.0" encoding="UTF-8"?>
<robot name="Robot">
    <link name="base">
        <inertial>
            <mass value="0"/>
            <inertia ixx="0" ixy="0" ixz="0" iyy="0" iyz="0" izz="0"/>
        </inertial>
    </link>
    <link name="base_link_prismatic">
        <inertial>
            <origin rpy="0.00000000 0.00000000 0.00000000" xyz="0.00000000 0.00000000 0.00000000"/>
            <mass value="1.00000000"/>
            <inertia ixx="1.00000000" ixy="0.00000000" ixz="0.00000000" iyy="1.00000000" iyz="0.00000000" izz="1.00000000"/>
        </inertial>
        <visual>
            <origin rpy="3.14159265 0.00000000 0.00000000" xyz="0.00000000 0.00000000 0.170000"/>
            <geometry>
                <mesh filename="/Users/kim/Documents/MATLAB/New Folder/path_planning/Basis_V5_scaled.stl" scale="1.00000000 1.00000000 1.00000000"/>
            </geometry>
            <material name="">
                <color rgba="0.50000000 0.50000000 0.50000000 1.00000000"/>
            </material>
        </visual>
    </link>
    <link name="link1">
        <inertial>
            <origin rpy="0.00000000 0.00000000 0.00000000" xyz="0.00000000 0.00000000 0.00000000"/>
            <mass value="1.00000000"/>
            <inertia ixx="0.20000000" ixy="0.00000000" ixz="0.00000000" iyy="0.10000000" iyz="0.00000000" izz="0.20000000"/>
        </inertial>
        <visual>
            <origin rpy="0.00000000 0.00000000 0.00000000" xyz="0.00000000 0.00000000 0.00000000"/>
            <geometry>
                <box size="0.03000000 0.0300000 0.02000000"/>
            </geometry>
            <material name="">
                <color rgba="0.50000000 0.50000000 0.50000000 1.00000000"/>
            </material>
        </visual>
        <collision>
            <origin rpy="0.00000000 0.00000000 0.00000000" xyz="0.00000000 0.00000000 0.0000000"/>
            <geometry>
                <box size="0.09000000 0.09000000 0.02000000"/>
            </geometry>
        </collision>
    </link>
    <link name="link2">
        <inertial>
            <origin rpy="0.00000000 0.00000000 0.00000000" xyz="0.00000000 0.00000000 0.00000000"/>
            <mass value="1.00000000"/>
            <inertia ixx="0.20000000" ixy="0.00000000" ixz="0.00000000" iyy="0.10000000" iyz="0.00000000" izz="0.20000000"/>
        </inertial>
        <visual>
            <origin rpy="0.00000000 0.00000000 0.00000000" xyz="0.12615000  0.00000000 -0.01550000"/>
            <geometry>
                <box size="0.25230000  0.05000000 0.03100000"/>
            </geometry>
            <material name="">
                <color rgba="0.50000000 0.50000000 0.50000000 1.00000000"/>
            </material>
        </visual>
        <collision>
            <origin rpy="0.00000000 0.00000000 0.00000000" xyz="0.12615000  0.00000000 -0.01550000"/>
            <geometry>
                <box size="0.25230000  0.05000000 0.03100000"/>
            </geometry>
        </collision>
    </link>
    <link name="link3">
        <inertial>
            <origin rpy="0.00000000 0.00000000 0.00000000" xyz="0.00000000 0.00000000 0.00000000"/>
            <mass value="1.00000000"/>
            <inertia ixx="0.20000000" ixy="0.00000000" ixz="0.00000000" iyy="0.10000000" iyz="0.00000000" izz="0.20000000"/>
        </inertial>
        <visual>
            <origin rpy="0.00000000 0.00000000 0.00000000" xyz="0.00000000 -0.07780000  0.00000000"/>
            <geometry>
                <box size="0.05000000 0.15560000  0.05000000"/>
            </geometry>
            <material name="">
                <color rgba="0.50000000 0.50000000 0.50000000 1.00000000"/>
            </material>
        </visual>
        <collision>
            <origin rpy="0.00000000 0.00000000 0.00000000" xyz="0.00000000 -0.07780000  0.00000000"/>
            <geometry>
                <box size="0.05000000 0.15560000  0.05000000"/>
            </geometry>
        </collision>
    </link>
    <link name="link4">
        <inertial>
            <origin rpy="0.00000000 0.00000000 0.00000000" xyz="0.00000000 0.00000000 0.00000000"/>
            <mass value="1.00000000"/>
            <inertia ixx="0.20000000" ixy="0.00000000" ixz="0.00000000" iyy="0.10000000" iyz="0.00000000" izz="0.20000000"/>
        </inertial>
        <visual>
            <origin rpy="0.00000000 0.00000000 0.00000000" xyz="0.00000000 0 0.02225000 "/>
            <geometry>
                <box size="0.05000000 0.04450000 0.05000000"/>
            </geometry>
            <material name="">
                <color rgba="0.50000000 0.50000000 0.50000000 1.00000000"/>
            </material>
        </visual>
        <collision>
            <origin rpy="0.00000000 0.00000000 0.00000000" xyz="0.00000000 0.00000000 0.02225000 "/>
            <geometry>
                <box size="0.05000000 0.04450000 0.05000000"/>
            </geometry>
        </collision>
    </link>
    <link name="link5">
        <inertial>
            <origin rpy="0.00000000 0.00000000 0.00000000" xyz="0.00000000 0.00000000 0.00000000"/>
            <mass value="1.00000000"/>
            <inertia ixx="0.20000000" ixy="0.00000000" ixz="0.00000000" iyy="0.10000000" iyz="0.00000000" izz="0.20000000"/>
        </inertial>
        <visual>
            <origin rpy="0.00000000 0.00000000 0.00000000" xyz="0  -0.01880000  0.04105"/>
            <geometry>
                <box size="-0.03760000  0.05000000  0.03760000"/>
            </geometry>
            <material name="">
                <color rgba="0.50000000 0.50000000 0.50000000 1.00000000"/>
            </material>
        </visual>
        <collision>
            <origin rpy="0.00000000 0.00000000 0.00000000" xyz="0.00000000 -0.01880000 0.04105"/>
            <geometry>
                <box size="0.03760000  0.05000000  0.03760000"/>
            </geometry>
        </collision>
    </link>
    <link name="link6">
        <inertial>
            <origin rpy="0.00000000 0.00000000 0.00000000" xyz="0.00000000 0.00000000 0.00000000"/>
            <mass value="1.00000000"/>
            <inertia ixx="0.20000000" ixy="0.00000000" ixz="0.00000000" iyy="0.10000000" iyz="0.00000000" izz="0.20000000"/>
        </inertial>
        <visual>
            <origin rpy="0.00000000 0.00000000 0.00000000" xyz="0.00000000 0.00000000 0.01000000"/>
            <geometry>
                <box size="0.02000000 0.02000000 0.02000000"/>
            </geometry>
            <material name="">
                <color rgba="0.50000000 0.50000000 0.50000000 1.00000000"/>
            </material>
        </visual>
        <collision>
            <origin rpy="0.00000000 0.00000000 0.00000000" xyz="0.00000000 0.00000000 0.01000000"/>
            <geometry>
                <box size="0.02000000 0.02000000 0.02000000"/>
            </geometry>
        </collision>
    </link>
    <link name="tool">
        <inertial>
            <origin rpy="0.00000000 0.00000000 0.00000000" xyz="0.00000000 0.00000000 0.00000000"/>
            <mass value="1.00000000"/>
            <inertia ixx="1.00000000" ixy="0.00000000" ixz="0.00000000" iyy="1.00000000" iyz="0.00000000" izz="1.00000000"/>
        </inertial>
        <visual>
            <origin rpy="-1.57079633  0.00000000  0.00000000" xyz="0.00000000  0.00000000 -0.11800000"/>
            <geometry>
                <mesh filename="/Users/kim/Documents/MATLAB/New Folder/path_planning/SIEM_Spritze.stl" scale="0.001000000 0.001000000 0.001000000"/>
            </geometry>
            <material name="">
                <color rgba="0.50000000 0.50000000 0.50000000 1.00000000"/>
            </material>
        </visual>
        <collision>
            <origin rpy="-1.57079633  0.00000000  0.00000000" xyz="0.00000000  0.00000000 -0.11800000"/>
            <geometry>
                <mesh filename="SIEM_Spritze.stl" scale="0.001000000 0.001000000 0.001000000"/>
            </geometry>
        </collision>
    </link>
    <joint name="base_slide" type="prismatic">
        <parent link="base"/>
        <child link="base_link_prismatic"/>
        <origin rpy="3.14159265 0.00000000 0.00000000" xyz="0.00000000 0.18000000 0.84000000"/>
        <axis xyz="1.00000000 0.00000000 0.00000000"/>
        <limit lower="0.00000000" upper="2.27000000" effort="0" velocity="0"/>
    </joint>
    <joint name="joint1" type="revolute">
        <parent link="base_link_prismatic"/>
        <child link="link1"/>
        <origin rpy="3.14159231 0.00000000 0.00000000" xyz="0.00000000 0.00000000 0.17000000"/>
        <axis xyz="0.00000000 0.00000000 1.00000000"/>
        <limit lower="-0.8713" upper="2.45744" effort="0" velocity="0"/>
    </joint>
    <joint name="joint2" type="revolute">
        <parent link="link1"/>
        <child link="link2"/>
        <origin rpy="-1.57079600  0.00000000  0.00000000" xyz="0.00000000 0.00000000 0.00000000"/>
        <axis xyz="0.00000000 0.00000000 1.00000000"/>
        <limit lower="0.20249" upper="2.50805569" effort="0" velocity="0"/>
    </joint>
    <joint name="joint3" type="revolute">
        <parent link="link2"/>
        <child link="link3"/>
        <origin rpy="0.00000000 0.00000000 0.00000000" xyz="0.25230000  0.00000000 -0.03100000"/>
        <axis xyz="0.00000000 0.00000000 1.00000000"/>
        <limit lower="-1.57079632679" upper="3.38396645" effort="0" velocity="0"/>
    </joint>
    <joint name="joint4" type="revolute">
        <parent link="link3"/>
        <child link="link4"/>
        <origin rpy="1.57079600 0.00000000 0.00000000" xyz="0.00000000 -0.15560000  0.00000000"/>
        <axis xyz="0.00000000 0.00000000 1.00000000"/>
        <limit lower="-2.06320596" upper="1.23639119" effort="0" velocity="0"/>
    </joint>
    <joint name="joint5" type="revolute">
        <parent link="link4"/>
        <child link="link5"/>
        <origin rpy="1.57079600 0.00000000 0.00000000" xyz="0.00000000 0.00000000 0.04450000"/>
        <axis xyz="0.00000000 0.00000000 1.00000000"/>
        <limit lower="-3.66773963" upper="1.34376383" effort="0" velocity="0"/>
    </joint>
    <joint name="joint6" type="revolute">
        <parent link="link5"/>
        <child link="link6"/>
        <origin rpy="-1.57079600  0.00000000  0.00000000" xyz="0  0.00000000  0.03760000"/>
        <axis xyz="0.00000000 0.00000000 1.00000000"/>
        <limit lower="-1.45881605" upper="2.77343297" effort="0" velocity="0"/>
    </joint>
    <joint name="tool_joint" type="fixed">
        <parent link="link6"/>
        <child link="tool"/>
        <origin rpy="0.00000000 1.57079633 0.00000000" xyz="0.14000000 0.00000000 0.06500000"/>
         <axis xyz="0.00000000 0.00000000 0.00000000"/>
    </joint>
</robot>
